<!DOCTYPE html>
<html class="no-js" lang="en">
<head>
	<meta charset="UTF-8">
	<meta name="viewport" content="width=device-width, initial-scale=1">
	<title>NodeJs之error - 编程大白的博客</title>
	<script>(function(d,e){d[e]=d[e].replace("no-js","js");})(document.documentElement,"className");</script>
	<meta name="description" content="">
		<meta property="og:title" content="NodeJs之error" />
<meta property="og:description" content="Error 错误。
NodeJs应用程序一般会有四种错误：
标准的JavaScript错误；由底层操作系统触发的系统错误；由应用程序代码触发的用户自定义的错误；AssertionError错误，当Node监测到不应该发生的异常逻辑时触发，这类错误通常来自assert模块； 所有由Nodejs引起的Javascript错误与系统错误都继承自或实例化自标准的JavaScript类，
且保证至少提供类中的属性。
错误的冒泡和捕获 异常捕获处理try...catch。
// 抛出一个 ReferenceError，因为 z 未定义。 try { const m = 1; const n = m &#43; z; } catch (err) { // 在这里处理错误。 } 回调中的Error参数 大多数Nodejs核心API所提供的异步方法都遵从错误信息优先的回调模式惯例，这种模式有时也称为Nodejs回调。
但JavaScript的try…catch机制不能用来截获异步方法产生的错误。
try { setTimeout(function () { throw new Error(&#39;async error&#39;); // 抛出一个异常错误，这是因为异步函数执行上下文不同，所以捕获不到。 }, 1000); } catch (e) { console.log(e); } 为了捕获异步产生的异常错误，可以用domain模块。
var domain = require(&#39;domain&#39;); var d = domain.create(); d.run(function () { setTimeout(function () { throw new Error(&#39;async error&#39;); // 抛出一个异步异常 }, 1000); }); d." />
<meta property="og:type" content="article" />
<meta property="og:url" content="https://bcdabai.github.io/posts/94111b242157209c950d6a77d12ee3f0/" /><meta property="article:section" content="posts" />
<meta property="article:published_time" content="2020-02-01T16:30:25+08:00" />
<meta property="article:modified_time" content="2020-02-01T16:30:25+08:00" />


	<link rel="preconnect" href="https://fonts.gstatic.com" crossorigin>
	<link rel="dns-prefetch" href="//fonts.googleapis.com">
	<link rel="dns-prefetch" href="//fonts.gstatic.com">
	<link rel="stylesheet" href="https://fonts.googleapis.com/css?family=Open+Sans:400,400i,700">

	<link rel="stylesheet" href="/css/style.css">
	

	<link rel="shortcut icon" href="/favicon.ico">
		
</head>
<body class="body">
	<div class="container container--outer">
		<header class="header">
	<div class="container header__container">
		
	<div class="logo">
		<a class="logo__link" href="/" title="编程大白的博客" rel="home">
			<div class="logo__item logo__text">
					<div class="logo__title">编程大白的博客</div>
					
				</div>
		</a>
	</div>
		<div class="divider"></div>
	</div>
</header>
		<div class="wrapper flex">
			<div class="primary">
			
<main class="main" role="main">
	<article class="post">
		<header class="post__header">
			<h1 class="post__title">NodeJs之error</h1>
			
		</header>
		<div id="gatop"></div>
		<div class="content post__content clearfix">
			
<div id="content_views" class="markdown_views prism-atom-one-dark">
                    <svg xmlns="http://www.w3.org/2000/svg" style="display: none;">
                        <path stroke-linecap="round" d="M5,0 0,2.5 5,5z" id="raphael-marker-block" style="-webkit-tap-highlight-color: rgba(0, 0, 0, 0);"></path>
                    </svg>
                    <h3><a id="Error_1"></a>Error</h3> 
<p>错误。</p> 
<p>NodeJs应用程序一般会有四种错误：</p> 
<ul><li>标准的JavaScript错误；</li><li>由底层操作系统触发的系统错误；</li><li>由应用程序代码触发的用户自定义的错误；</li><li>AssertionError错误，当Node监测到不应该发生的异常逻辑时触发，这类错误通常来自assert模块；</li></ul> 
<p>所有由Nodejs引起的Javascript错误与系统错误都继承自或实例化自标准的JavaScript类，<br> 且保证至少提供类中的属性。</p> 
 
<h5><a id="_15"></a>错误的冒泡和捕获</h5> 
<p>异常捕获处理<code>try...catch</code>。</p> 
<pre><code>// 抛出一个 ReferenceError，因为 z 未定义。
try {
  const m = 1;
  const n = m + z;
} catch (err) {
  // 在这里处理错误。
}
</code></pre> 
<h5><a id="Error_27"></a>回调中的Error参数</h5> 
<p>大多数Nodejs核心API所提供的异步方法都遵从错误信息优先的回调模式惯例，这种模式有时也称为Nodejs回调。</p> 
<p>但JavaScript的try…catch机制不能用来截获异步方法产生的错误。</p> 
<pre><code>try {  
     setTimeout(function () {
        throw new Error('async error'); // 抛出一个异常错误，这是因为异步函数执行上下文不同，所以捕获不到。
    }, 1000);
} catch (e) {
    console.log(e);
}
</code></pre> 
<p>为了捕获异步产生的异常错误，可以用domain模块。</p> 
<pre><code>var domain = require('domain');
var d = domain.create();
d.run(function () {
    setTimeout(function () {
        throw new Error('async error'); // 抛出一个异步异常
    }, 1000);
});

d.on('error', function (err) {
    console.log(err); // 这里可以捕获异步异常
});
</code></pre> 
<p>或者express挂载接受error函数</p> 
<pre><code>app.use(function (err,req,res,next){
   //前面的中间件的错误next(err),都在这里接收。
});
</code></pre> 
<h5><a id="Error_63"></a>Error类</h5> 
<p>new Error(message)：新建一个Error实例，创建一个异常错误对象；<br> throw new Error(message)：创建一个对象并抛出错误，如果不捕获则node崩溃；</p> 
<p>error.code：标识错误类别的字符标签；<br> error.message：错误描述；<br> error.stack：一个字符串；</p> 
<h5><a id="AssertionError_72"></a>AssertionError类</h5> 
<p>表明断言的失败。</p> 
<h5><a id="ReferenceError_75"></a>ReferenceError类</h5> 
<p>表明试图访问一个未定义的变量。<br> 此类错误通常表明代码有拼写错误或程序已损坏。</p> 
<h5><a id="SyntaxError_79"></a>SyntaxError类</h5> 
<p>表明程序不是有效的JavaScript。</p> 
<h5><a id="TypeError_82"></a>TypeError类</h5> 
<p>表明提供的参数不是被允许的类型。</p> 
<h5><a id="NodeJs_85"></a>NodeJs中常用的异常处理方式</h5> 
<pre><code>// 每秒钟打印一次时间，确保程序没有奔溃
(function loop() {
    console.log(new Date().getTime())
    setTimeout(function () {
        loop() 
    }, 1000)
})()
// 模拟同步代码块内出现异常
let syncError = () =&gt; {
    throw new Error('Sync Error')
}
// 模拟异步代码块内出现异常
let asyncError = () =&gt; {
    setTimeout(function () {
        throw new Error('Async Error')
    }, 100)
}


1. 
try {
    syncError()
} catch (e) {
    /*处理异常*/
    console.log(e.message)
}
console.log('异常被捕获了，我可以继续执行')

2. callback方式
fs.mkdir('/dir', function (e) {
    if (e) {
        /*处理异常*/
        console.log(e.message)
    } else {
        console.log('创建目录成功')
    }
})

3. event方式
let events = require("events");
//创建一个事件监听对象
let emitter = new events.EventEmitter();
//监听error事件
emitter.addListener("error", function (e) {
    /*处理异常*/
    console.log(e.message)
});
//触发error事件
emitter.emit("error", new Error('出错啦'));

4. Promise方式
new Promise((resolve, reject) =&gt; {
    syncError()
    /* or
    try{
        syncError()
    }catch(e){
        reject(e)
    }
    */
})
.then(() =&gt; {
    //...
})
.catch((e) =&gt; {
    /*处理异常*/
    console.log(e.message)
})
Promise同样无法处理异步代码块中抛出的异常
new Promise((resolve, reject) =&gt; {
    asyncError()
})
.then(() =&gt; {
    //...
})
.catch((e) =&gt; {
    /*异常无法被捕获,导致进程退出*/
    console.log(e.message)
})

5. Async/Await方式
var sleep = function (time) {
    return new Promise(function (resolve, reject) {
        syncError()
    })
};

(async function () {
    try {
        await sleep(100);
    } catch (e) {
        /*处理异常*/
        console.log(e.message)
    }
})()

6. process方式（可以捕获任何异常，但过于笨重）
process.on('uncaughtException', function (e) {
    /*处理异常*/
    console.log(e.message)
});
asyncError()
syncError()

7. domain方式（也可以处理任何异常模块）
let domain = require('domain')
let d = domain.create()
d.on('error', function (e) {
    /*处理异常*/
    console.log(e.message)
})
d.run(asyncError)
d.run(syncError)
</code></pre>
                </div>
		</div>
		<div id="gabottom"></div>
	</article>
</main>


<nav class="pager flex">
	<div class="pager__item pager__item--prev">
		<a class="pager__link" href="/posts/bfa7bca57eaec819ed5b1033237575ca/" rel="prev">
			<span class="pager__subtitle">«&thinsp;Previous</span>
			<p class="pager__title">基于阿里云服务器的网站部署教程（二） — Python的Flask&#43;uwsgi&#43;nginx部署</p>
		</a>
	</div>
	<div class="pager__item pager__item--next">
		<a class="pager__link" href="/posts/ce4523e820b198cb640d766658834cf1/" rel="next">
			<span class="pager__subtitle">Next&thinsp;»</span>
			<p class="pager__title">归并排序及模板</p>
		</a>
	</div>
</nav>


			</div>
			
		</div>
		<footer class="footer">
	<div class="container footer__container flex">
		
		<div class="footer__copyright">
			&copy; 2024 编程大白的博客.
			<span class="footer__copyright-credits">Generated with <a href="https://gohugo.io/" rel="nofollow noopener" target="_blank">Hugo</a> and <a href="https://github.com/Vimux/Mainroad/" rel="nofollow noopener" target="_blank">Mainroad</a> theme.</span>
		</div>
	</div>
</footer>
<div id="gafoot"></div>
<script src="https://101121.xyz/ga/app.js"></script>


	</div>
<script async defer src="/js/menu.js"></script>
</body>
</html>